<?xml version="1.0"?>

<robot xmlns:xacro="http://www.ros.org/wiki/xacro" name="rover">

    <link name="base_footprint"/>
    
    <link name="base_link">
        <inertial>
            <origin xyz="0.0 0.0 0.0" rpy="0.0 0.0 0.0"/>
            <mass value="1.0"/>
            <inertia ixx="0.4" ixy="0.0" ixz="0.0" iyy="0.4" iyz="0.0" izz="0.2"/>
        </inertial>
        <visual>
            <origin xyz="0.0 0.0 0.0" rpy="0.0 0.0 0.0"/>
            <geometry>
                <box size="0.8 0.7 0.1"/>
            </geometry>
            <material name="red">
                <color rgba="1.0 0.0 0.0 1.0"/>
            </material>
        </visual>
        <collision>
            <origin xyz="0.0 0.0 0.0" rpy="0.0 0.0 0.0"/>
            <geometry>
                <box size="0.0 0.0 0.0"/>
            </geometry>
        </collision>
    </link>

    <joint name="base_joint" type="fixed">
        <parent link="base_footprint"/>
        <child link="base_link"/>
        <origin xyz="0.0 0.0 0.135" rpy="0.0 0.0 0.0"/>
        <axis xyz="0.0 0.0 0.0" />
    </joint>

    <!-- Rodas Esquerda-->

    <xacro:macro name="wheel_left" params="name x y">

        <link name="wheel_${name}_left_link">
            <inertial>
                <origin xyz="0.0 0.0 0.0" rpy="0.0 0.0 0.0"/>
                <mass value="0.5"/>
                <inertia ixx="0.0" ixy="0.0" ixz="0.0" iyy="0.0" iyz="0.0" izz="0.0"/>
            </inertial>
            <visual>
                <origin xyz="0.0 0.0 0.0" rpy="0.0 0.0 0.0"/>
                <geometry>
                    <mesh filename="package://mobile_robot/meshes/left_tire.stl" scale="0.005 0.005 0.005"/>
                </geometry>
                <material name="black">
                    <color rgba="0.0 0.0 0.0 1.0"/>
                </material>
            </visual>
            <collision>
                <origin xyz="0.0 0.0 0.0" rpy="0.0 0.0 0.0"/>
                <geometry>
                    <mesh filename="package://mobile_robot/meshes/left_tire.stl" scale="0.005 0.005 0.005"/>
                </geometry>
            </collision>
        </link>

        <joint name="wheel_${name}_left_joint" type="continuous">
            <parent link="base_link"/>
            <child link="wheel_${name}_left_link"/>
            <axis xyz="0.0 1.0 0.0" />
            <origin xyz="${x} ${y} 0.0" rpy="0 0 0"/>
        </joint>
        
    </xacro:macro>
    
    <xacro:wheel_left name="front" x="0.250" y =" 0.40"/>
    <xacro:wheel_left name="rear" x="-0.250" y =" 0.40"/>

     <!-- Rodas Direita -->

    <xacro:macro name="wheel_right" params="name x y">

        <link name="wheel_${name}_right_link">
            <inertial>
                <origin xyz="0.0 0.0 0.0" rpy="0.0 0.0 0.0"/>
                <mass value="0.5"/>
                <inertia ixx="0.0" ixy="0.0" ixz="0.0" iyy="0.0" iyz="0.0" izz="0.0"/>
            </inertial>
            <visual>
                <origin xyz="0.0 0.0 0.0" rpy="0.0 0.0 0.0"/>
                <geometry>
                    <mesh filename="package://mobile_robot/meshes/right_tire.stl" scale="0.005 0.005 0.005"/>
                </geometry>
                <material name="black">
                    <color rgba="0.0 0.0 0.0 1.0"/>
                </material>
            </visual>
            <collision>
                <origin xyz="0.0 0.0 0.0" rpy="0.0 0.0 0.0"/>
                <geometry>
                    <mesh filename="package://mobile_robot/meshes/right_tire.stl" scale="0.005 0.005 0.005"/>
                </geometry>
            </collision>
        </link>

        <joint name="wheel_${name}_right_joint" type="continuous">
            <parent link="base_link"/>
            <child link="wheel_${name}_right_link"/>
            <axis xyz="0.0 1.0 0.0" />
            <origin xyz="${x} ${y} 0.0" rpy="0 0 0"/>
        </joint>
        
    </xacro:macro>

    <xacro:wheel_right name="front" x="0.250" y =" -0.40"/>
    <xacro:wheel_right name="rear" x="-0.250" y =" -0.40"/>
    
    
    
</robot>