<?xml version="1.0"?>
<robot name="rover">

    <link name="base_footprint"/>
    
    <link name="base_link">
        <inertial>
            <origin xyz="0.0 0.0 0.0" rpy="0.0 0.0 0.0"/>
            <mass value="0.0"/>
            <inertia ixx="0.0" ixy="0.0" ixz="0.0" iyy="0.0" iyz="0.0" izz="0.0"/>
        </inertial>
        <visual>
            <origin xyz="0.0 0.0 0.0" rpy="0.0 0.0 0.0"/>
            <geometry>
                <box size="0.8 0.7 0.1"/>
            </geometry>
            <material name="red">
                <color rgba="1.0 0.0 0.0 1.0"/>
            </material>
        </visual>
        <collision>
            <origin xyz="0.0 0.0 0.0" rpy="0.0 0.0 0.0"/>
            <geometry>
                <box size="0.0 0.0 0.0"/>
            </geometry>
        </collision>
    </link>

    <joint name="base_joint" type="fixed">
        <parent link="base_footprint"/>
        <child link="base_link"/>
        <origin xyz="0.0 0.0 0.135" rpy="0.0 0.0 0.0"/>
        <axis xyz="0.0 0.0 0.0" />
    </joint>

    <!-- front right wheel -->
    
    <link name="wheel_front_right_link">
        <inertial>
            <origin xyz="0.0 0.0 0.0" rpy="0.0 0.0 0.0"/>
            <mass value="0.0"/>
            <inertia ixx="0.0" ixy="0.0" ixz="0.0" iyy="0.0" iyz="0.0" izz="0.0"/>
        </inertial>
        <visual>
            <origin xyz="0.0 0.0 0.0" rpy="0.0 0.0 0.0"/>
            <geometry>
                <cylinder radius="0.15" length="0.1"/>
            </geometry>
            <material name="black">
                <color rgba="0.0 0.0 0.0 1.0"/>
            </material>
        </visual>
        <collision>
            <origin xyz="0.0 0.0 0.0" rpy="0.0 0.0 0.0"/>
            <geometry>
                <cylinder radius="0.15" length="0.1"/>
            </geometry>
        </collision>
    </link>

    <joint name="wheel_front_right_joint" type="continuous">
        <parent link="base_link"/>
        <child link="wheel_front_right_link"/>
        <axis xyz="0.0 0.0 1.0" />
        <origin xyz="0.25 0.4 0.0" rpy="1.57 0 0"/>
    </joint>

    <!-- Front left wheel -->
    <link name="wheel_front_left_link">
        <inertial>
            <origin xyz="0.0 0.0 0.0" rpy="0.0 0.0 0.0"/>
            <mass value="0.0"/>
            <inertia ixx="0.0" ixy="0.0" ixz="0.0" iyy="0.0" iyz="0.0" izz="0.0"/>
        </inertial>
        <visual>
            <origin xyz="0.0 0.0 0.0" rpy="0.0 0.0 0.0"/>
            <geometry>
                <cylinder radius="0.15" length="0.1"/>
            </geometry>
            <material name="black">
                <color rgba="0.0 0.0 0.0 1.0"/>
            </material>
        </visual>
        <collision>
            <origin xyz="0.0 0.0 0.0" rpy="0.0 0.0 0.0"/>
            <geometry>
                <cylinder radius="0.15" length="0.1"/>
            </geometry>
        </collision>
    </link>

    <joint name="wheel_front_left_joint" type="continuous">
        <parent link="base_link"/>
        <child link="wheel_front_left_link"/>
        <axis xyz="0.0 0.0 1.0" />
        <origin xyz="0.25 -0.4 0.0" rpy="1.57 0 0"/>
    </joint>

     <!-- Rear right wheel -->
    
    <link name="wheel_rear_right_link">
        <inertial>
            <origin xyz="0.0 0.0 0.0" rpy="0.0 0.0 0.0"/>
            <mass value="0.0"/>
            <inertia ixx="0.0" ixy="0.0" ixz="0.0" iyy="0.0" iyz="0.0" izz="0.0"/>
        </inertial>
        <visual>
            <origin xyz="0.0 0.0 0.0" rpy="0.0 0.0 0.0"/>
            <geometry>
                <cylinder radius="0.15" length="0.1"/>
            </geometry>
            <material name="black">
                <color rgba="0.0 0.0 0.0 1.0"/>
            </material>
        </visual>
        <collision>
            <origin xyz="0.0 0.0 0.0" rpy="0.0 0.0 0.0"/>
            <geometry>
                <cylinder radius="0.15" length="0.1"/>
            </geometry>
        </collision>
    </link>

    <joint name="wheel_rear_right_joint" type="continuous">
        <parent link="base_link"/>
        <child link="wheel_rear_right_link"/>
        <axis xyz="0.0 0.0 1.0" />
        <origin xyz="-0.25 0.4 0.0" rpy="1.57 0 0"/>
    </joint>

    <!-- Rear left wheel -->
    <link name="wheel_rear_left_link">
        <inertial>
            <origin xyz="0.0 0.0 0.0" rpy="0.0 0.0 0.0"/>
            <mass value="0.0"/>
            <inertia ixx="0.0" ixy="0.0" ixz="0.0" iyy="0.0" iyz="0.0" izz="0.0"/>
        </inertial>
        <visual>
            <origin xyz="0.0 0.0 0.0" rpy="0.0 0.0 0.0"/>
            <geometry>
                <cylinder radius="0.15" length="0.1"/>
            </geometry>
            <material name="black">
                <color rgba="0.0 0.0 0.0 1.0"/>
            </material>
        </visual>
        <collision>
            <origin xyz="0.0 0.0 0.0" rpy="0.0 0.0 0.0"/>
            <geometry>
                <cylinder radius="0.15" length="0.1"/>
            </geometry>
        </collision>
    </link>

    <joint name="wheel_rear_left_joint" type="continuous">
        <parent link="base_link"/>
        <child link="wheel_rear_left_link"/>
        <axis xyz="0.0 0.0 1.0" />
        <origin xyz="-0.25 -0.4 0.0" rpy="1.57 0 0"/>
    </joint>
    
    
</robot>